* 11강 - try except로 예외처리하기

​

try except : 실행시간에 에러가 발생하여 코드가 중단되는 것을 방지

```python
try:
	<예외 발생 가능성이 있는 문장>
except <예외 종류>:   # 특정 에러가 발생한 경우
	<예외 처리 문장>
except (예외1, 예외2):   # 여러 개의 에러 중 하나에 해당
	<예외 처리 문장>
except 예외 as 인자:   # 에러를 as 뒤의 값으로 부를 수 있음
	<예외 처리 문장>
else:
	<예외가 발생하지 않은 경우 수행될 문장>
finally:
	<예외 발생 유무와 상관없이 try 블록 이후 수행할 문장>
```
​


```python
def divide (a, b):
	return a / b

try:
	c = divide(5, 'string')
except ZeroDivisionError:
	print('두 번째 인자는 0이여서는 안됨')
except TypeError:
	print('모든 인자는 숫자여야 함')
except:
	print('음 무슨 에러인지 모르겠음')
```

​

```python
def divide (a, b):
	return a / b
	
try:
	c = divide(5, 'string')
except ZeroDivisionError:
	print('두 번째 인자는 0이여서는 안됨')
except TypeError:
	print('모든 인자는 숫자여야 함')
except:
	print('ZeroDivisionError, TypeError를 제외한 다른 에러')
else:
	print('Result:{0}'.format(c))   # 에러가 나지 않을 경우 수행
finally:
	print('항상 finally 블록은 수행됨')
```
​
​

* 12강 - 사용자 정의 예외 클래스 사용하기

​

raise 구문 : 사용자가 강제로 예외를 일으킬 때 사용하는 구문

```python
def raiseErrorFunc():
	raise NameError

try:
	raiseErrorFunc()   # NameError를 강제로 일으킴
except:
	print("NameError is Catched")
```

​

내장 예외만으로 한계가 있어 사용자 정의 예외를 정의할 수 있다

```python
class NegativeDivisionError(Exception):  # Exception 클래스를 상속받음
	def __init__(self, value):   # 생성자 메소드
		self.value = value   # value는 생성자 메소드에 의해 내부에 초기화되는 값

def positiveDivide(a, b):
	if(b < 0):  # 0보다 작다면 NegativeDivisionError 발생
		raise NegativeDivisionError(b)
	return a / b

try:
    ret = positiveDivide(10, -3)    # 일부러 에러 발생
    print('10 / 3 = {0}'.format(ret))
except NegativeDivisionError as e:
    print('Error - Second argument of PositiveDivide is ', e.value)   # e.value = b = value
except ZeroDivisionError as e:
    print('Error - ', e.args[0])
```

​

사용자 정의 Exception 클래스는 부모 클래스로부터 Exception 클래스를 상속받아야 한다

